<?xml version="1.0"?>
<robot name="my_robot">
    <link name="base_link"/>
    <link name="wrist_3_link"/>
    <joint name="wrist_3_joint" type="revolute">
        <parent link="base_link"/>
        <child link="wrist_3_link"/>
        <origin xyz="0 0 0" rpy="0 0 0"/>
        <axis xyz="0 0 1"/>
        <limit effort="1000.0" lower="-1.57" upper="1.57" velocity="1.0"/>
        <gazebo reference="wrist_3_joint">
            <provideFeedback>true</provideFeedback>
        </gazebo>
    </joint>
</robot>
