<?xml version="1.0" ?>
<!-- =================================================================================== -->
<!-- |    This document was autogenerated by xacro from /home/robat/.localgit/goldilocks_sensibility_ws/src/bdr11_description/urdf/bdr11.urdf.xacro | -->
<!-- |    EDITING THIS FILE BY HAND IS NOT RECOMMENDED                                 | -->
<!-- =================================================================================== -->
<robot name="dual_robots">
    <!-- Define the world link -->
    <link name="world" />
    <!--https://github.com/carlosjoserg/force-torque-sensor/tree/master/model-->
    <!-- Add feedback for camera-related joints -->
    <gazebo reference="rgbd_camera_joint">
        <provideFeedback>true</provideFeedback>
        <plugin name="gazebo_ros_control" filename="libgazebo_ros_control.so">
            <robotNamespace>/</robotNamespace>
        </plugin>
    </gazebo>
    <gazebo reference="rgbd_camera_optical_joint">
        <provideFeedback>true</provideFeedback>
    </gazebo>
    <gazebo reference="rgbd_camera_depth_joint">
        <provideFeedback>true</provideFeedback>
    </gazebo>
    <gazebo reference="rgbd_camera_depth_optical_joint">
        <provideFeedback>true</provideFeedback>
    </gazebo>
    <gazebo reference="rgbd_camera_rgb_joint">
        <provideFeedback>true</provideFeedback>
    </gazebo>
    <gazebo reference="rgbd_camera_rgb_optical_joint">
        <provideFeedback>true</provideFeedback>
    </gazebo>
    <gazebo reference="rgbd_camera_link">
        <!-- Depth (IR) -->
        <sensor name="rgbd_camera_frame_sensor" type="depth">
            <always_on>true</always_on>
            <update_rate>6.0</update_rate>
            <camera>
                <horizontal_fov>1.0122909661567112</horizontal_fov>
                <image>
                    <format>R8G8B8</format>
                    <width>800</width>
                    <height>600</height>
                </image>
                <clip>
                    <near>0.05</near>
                    <far>1.5</far>
                </clip>
            </camera>
            <plugin filename="libgazebo_ros_openni_kinect.so" name="rgbd_camera_frame_controller">
                <alwaysOn>true</alwaysOn>
                <updateRate>6.0</updateRate>
                <cameraName>rgbd_camera</cameraName>
                <imageTopicName>ir/image_raw</imageTopicName>
                <cameraInfoTopicName>ir/camera_info</cameraInfoTopicName>
                <depthImageTopicName>depth/image_raw</depthImageTopicName>
                <depthImageCameraInfoTopicName>depth/camera_info</depthImageCameraInfoTopicName>
                <pointCloudTopicName>depth/points</pointCloudTopicName>
                <frameName>rgbd_camera_optical_frame</frameName>
                <pointCloudCutoff>0.05</pointCloudCutoff>
                <pointCloudCutoffMax>5</pointCloudCutoffMax>
                <rangeMax>1.5</rangeMax>
            </plugin>
        </sensor>
        <!-- RGB -->
        <sensor name="rgbd_camera_frame_sensor" type="depth">
            <always_on>true</always_on>
            <update_rate>6.0</update_rate>
            <camera>
                <horizontal_fov>1.0122909661567112</horizontal_fov>
                <image>
                    <format>R8G8B8</format>
                    <width>800</width>
                    <height>600</height>
                </image>
                <clip>
                    <near>0.05</near>
                    <far>1.5</far>
                </clip>
            </camera>
            <plugin filename="libgazebo_ros_openni_kinect.so" name="rgbd_camera_frame_controller">
                <alwaysOn>true</alwaysOn>
                <updateRate>6.0</updateRate>
                <cameraName>rgbd_camera</cameraName>
                <imageTopicName>rgb/image_raw</imageTopicName>
                <cameraInfoTopicName>rgb/camera_info</cameraInfoTopicName>
                <pointCloudTopicName>rgb/points</pointCloudTopicName>
                <depthImageTopicName>depth/image_raw</depthImageTopicName>
                <depthImageCameraInfoTopicName>depth/camera_info</depthImageCameraInfoTopicName>
                <frameName>rgbd_camera_optical_frame</frameName>
                <pointCloudCutoff>0.05</pointCloudCutoff>
                <pointCloudCutoffMax>5</pointCloudCutoffMax>
                <rangeMax>1.5</rangeMax>
            </plugin>
        </sensor>
        <!-- Add feedback for camera link -->
        <provideFeedback>true</provideFeedback>
    </gazebo>
    <!-- call -->
    <!-- <xacro:ur10_robot/> -->
    <link name="table_link">
        <inertial>
            <origin rpy="0 0 0" xyz="0.503679778923471 0.436750246454337 0.533162239913515" />
            <mass value="164.427518164029" />
            <inertia ixx="17.5438109681455" ixy="1.00173029919582" ixz="-0.84554880731535" iyy="27.9962527469498" iyz="0.32261270489944" izz="25.3196927520228" />
        </inertial>
        <visual>
            <origin rpy="0 0 0" xyz="0 0 0" />
            <geometry>
                <mesh filename="package://ur10_description_v3/meshes/table_link.STL" />
            </geometry>
            <material name="">
                <color rgba="0.752941176470588 0.752941176470588 0.752941176470588 1" />
            </material>
        </visual>
        <collision>
            <origin rpy="0 0 0" xyz="0 0 0" />
            <geometry>
                <mesh filename="package://ur10_description_v3/meshes/table_link.STL" />
            </geometry>
        </collision>
    </link>
    <link name="adapter_link">
        <inertial>
            <origin rpy="0 0 0" xyz="0.00148762870939384 -5.55111512312578E-17 0.0184969952138566" />
            <mass value="1.3940393775037" />
            <inertia ixx="0.00480218257555222" ixy="-3.32761202584861E-19" ixz="-6.23136456619299E-09" iyy="0.00460995913579551" iyz="-9.9318015210222E-20" izz="0.00909416459764461" />
        </inertial>
        <visual>
            <origin rpy="0 0 0" xyz="0 0 0" />
            <geometry>
                <mesh filename="package://ur10_description_v3/meshes/adapter_link.STL" />
            </geometry>
            <material name="">
                <color rgba="0.752941176470588 0.752941176470588 0.752941176470588 1" />
            </material>
        </visual>
        <collision>
            <origin rpy="0 0 0" xyz="0 0 0" />
            <geometry>
                <mesh filename="package://ur10_description_v3/meshes/adapter_link.STL" />
            </geometry>
        </collision>
    </link>
    <joint name="adapter_joint" type="fixed">
        <origin rpy="0 0 0" xyz="0.17 0.4 0.9" />
        <parent link="table_link" />
        <child link="adapter_link" />
        <axis xyz="0 0 0" />
    </joint>
    <link name="base_link">
        <inertial>
            <origin rpy="0 0 0" xyz="0.0011845 -2.7253E-08 0.017325" />
            <mass value="0.86268" />
            <inertia ixx="0.0017501" ixy="8.3495E-09" ixz="9.0593E-06" iyy="0.0016637" iyz="-4.5806E-10" izz="0.0032119" />
        </inertial>
        <visual>
            <origin rpy="0 0 0" xyz="0 0 0" />
            <geometry>
                <mesh filename="package://ur10_description_v3/meshes/base_link.STL" />
            </geometry>
            <material name="">
                <color rgba="0.75294 0.75294 0.75294 1" />
            </material>
        </visual>
        <collision>
            <origin rpy="0 0 0" xyz="0 0 0" />
            <geometry>
                <mesh filename="package://ur10_description_v3/meshes/base_link.STL" />
            </geometry>
        </collision>
    </link>
    <joint name="base_joint" type="fixed">
        <origin rpy="0 0 0" xyz="0 0 0.037" />
        <parent link="adapter_link" />
        <child link="base_link" />
        <axis xyz="0 0 0" />
    </joint>
    <link name="shoulder_link">
        <inertial>
            <origin rpy="0 0 0" xyz="2.679E-07 0.010024 0.0831" />
            <mass value="7.778" />
            <inertia ixx="0.012906" ixy="1.6076E-08" ixz="-3.7079E-08" iyy="0.012039" iyz="-0.00053627" izz="0.010755" />
        </inertial>
        <visual>
            <origin rpy="0 0 0" xyz="0 0 0" />
            <geometry>
                <mesh filename="package://ur10_description_v3/meshes/shoulder_link.STL" />
            </geometry>
            <material name="">
                <color rgba="0.25098 0.25098 0.25098 1" />
            </material>
        </visual>
        <collision>
            <origin rpy="0 0 0" xyz="0 0 0" />
            <geometry>
                <mesh filename="package://ur10_description_v3/meshes/shoulder_link.STL" />
            </geometry>
        </collision>
    </link>
    <joint name="shoulder_pan_joint" type="revolute">
        <origin rpy="0 0 -1.57" xyz="0 0 0.038" />
        <parent link="base_link" />
        <child link="shoulder_link" />
        <axis xyz="0 0 1" />
        <limit effort="330" lower="-6.28" upper="6.28" velocity="120" />
    </joint>
    <link name="upper_arm_link">
        <inertial>
            <origin rpy="0 0 0" xyz="-0.25443 -2.027E-07 0.082537" />
            <mass value="12.93" />
            <inertia ixx="0.024456" ixy="3.1971E-08" ixz="0.0078193" iyy="0.52575" iyz="8.3512E-08" izz="0.52417" />
        </inertial>
        <visual>
            <origin rpy="0 0 0" xyz="0 0 0" />
            <geometry>
                <mesh filename="package://ur10_description_v3/meshes/upper_arm_link.STL" />
            </geometry>
            <material name="">
                <color rgba="0.25098 0.25098 0.25098 1" />
            </material>
        </visual>
        <collision>
            <origin rpy="0 0 0" xyz="0 0 0" />
            <geometry>
                <mesh filename="package://ur10_description_v3/meshes/upper_arm_link.STL" />
            </geometry>
        </collision>
    </link>
    <joint name="shoulder_lift_joint" type="revolute">
        <origin rpy="1.5707963267949 0.0240929901040578 3.14159265358979" xyz="0 0.0859989999999999 0.0882571802206784" />
        <parent link="shoulder_link" />
        <child link="upper_arm_link" />
        <axis xyz="0 0 1" />
        <limit effort="330" lower="-6.28" upper="6.28" velocity="120" />
    </joint>
    <link name="forearm_link">
        <inertial>
            <origin rpy="0 0 0" xyz="-0.24807 1.9251E-09 -0.034936" />
            <mass value="3.87" />
            <inertia ixx="0.0067905" ixy="5.4328E-08" ixz="-0.00025402" iyy="0.20899" iyz="7.4389E-09" izz="0.20875" />
        </inertial>
        <visual>
            <origin rpy="0 0 0" xyz="0 0 0" />
            <geometry>
                <mesh filename="package://ur10_description_v3/meshes/forearm_link.STL" />
            </geometry>
            <material name="">
                <color rgba="0.25098 0.25098 0.25098 1" />
            </material>
        </visual>
        <collision>
            <origin rpy="0 0 0" xyz="0 0 0" />
            <geometry>
                <mesh filename="package://ur10_description_v3/meshes/forearm_link.STL" />
            </geometry>
        </collision>
    </link>
    <joint name="elbow_joint" type="revolute">
        <origin rpy="0 0 0.0242666741712824" xyz="-0.612 0 0" />
        <parent link="upper_arm_link" />
        <child link="forearm_link" />
        <axis xyz="0 0 1" />
        <limit effort="150" lower="-3.14" upper="3.14" velocity="180" />
    </joint>
    <link name="wrist_1_link">
        <inertial>
            <origin rpy="0 0 0" xyz="8.3814E-09 -0.010045 0.046994" />
            <mass value="1.96" />
            <inertia ixx="0.0010747" ixy="-1.3405E-12" ixz="4.6386E-10" iyy="0.00088168" iyz="7.862E-05" izz="0.00098347" />
        </inertial>
        <visual>
            <origin rpy="0 0 0" xyz="0 0 0" />
            <geometry>
                <mesh filename="package://ur10_description_v3/meshes/wrist_1_link.STL" />
            </geometry>
            <material name="">
                <color rgba="0.25098 0.25098 0.25098 1" />
            </material>
        </visual>
        <collision>
            <origin rpy="0 0 0" xyz="0 0 0" />
            <geometry>
                <mesh filename="package://ur10_description_v3/meshes/wrist_1_link.STL" />
            </geometry>
        </collision>
    </link>
    <joint name="wrist_1_joint" type="revolute">
        <origin rpy="0 0 -0.000173684067224549" xyz="-0.5716 0 0.0220010000000001" />
        <parent link="forearm_link" />
        <child link="wrist_1_link" />
        <axis xyz="0 0 1" />
        <limit effort="56" lower="-6.28" upper="6.28" velocity="180" />
    </joint>
    <link name="wrist_2_link">
        <inertial>
            <origin rpy="0 0 0" xyz="-8.3814E-09 0.010045 0.046994" />
            <mass value="1.96" />
            <inertia ixx="0.0010747" ixy="-1.3405E-12" ixz="-4.6386E-10" iyy="0.00088168" iyz="-7.862E-05" izz="0.00098347" />
        </inertial>
        <visual>
            <origin rpy="0 0 0" xyz="0 0 0" />
            <geometry>
                <mesh filename="package://ur10_description_v3/meshes/wrist_2_link.STL" />
            </geometry>
            <material name="">
                <color rgba="0.25098 0.25098 0.25098 1" />
            </material>
        </visual>
        <collision>
            <origin rpy="0 0 0" xyz="0 0 0" />
            <geometry>
                <mesh filename="package://ur10_description_v3/meshes/wrist_2_link.STL" />
            </geometry>
        </collision>
    </link>
    <joint name="wrist_2_joint" type="revolute">
        <origin rpy="1.5707963267949 0 0" xyz="0 -0.0617000000000001 0.054" />
        <parent link="wrist_1_link" />
        <child link="wrist_2_link" />
        <axis xyz="0 0 1" />
        <limit effort="56" lower="-6.28" upper="6.28" velocity="180" />
    </joint>
    <link name="wrist_3_link">
        <inertial>
            <origin rpy="0 0 0" xyz="2.2204E-16 -1.1102E-16 0.015005" />
            <mass value="0.202" />
            <inertia ixx="0.00010845" ixy="-6.3527E-22" ixz="8.5217E-21" iyy="0.00010845" iyz="2.1272E-20" izz="0.0001885" />
        </inertial>
        <visual>
            <origin rpy="0 0 0" xyz="0 0 0" />
            <geometry>
                <mesh filename="package://ur10_description_v3/meshes/wrist_3_link.STL" />
            </geometry>
            <material name="">
                <color rgba="0.75294 0.75294 0.75294 1" />
            </material>
        </visual>
        <collision>
            <origin rpy="0 0 0" xyz="0 0 0" />
            <geometry>
                <mesh filename="package://ur10_description_v3/meshes/wrist_3_link.STL" />
            </geometry>
        </collision>
    </link>
    <joint name="wrist_3_joint" type="revolute">
        <origin rpy="-1.5707963267949 0.0141025375343068 0" xyz="0 0.0617 0.054" />
        <parent link="wrist_2_link" />
        <child link="wrist_3_link" />
        <axis xyz="0 0 1" />
        <limit effort="56" lower="-6.28" upper="6.28" velocity="180" />
    </joint>
    <link name="tool0_link">
        <inertial>
            <origin rpy="0 0 0" xyz="-9.51811385263568E-09 -0.00040829549117638 -0.063076624107084" />
            <mass value="0.159494248297753" />
            <inertia ixx="0.000196142213229152" ixy="-3.17147593634008E-12" ixz="-8.16590451397829E-11" iyy="0.000202558472496363" iyz="3.31143649078889E-05" izz="0.000103928487892553" />
        </inertial>
        <visual>
            <origin rpy="0 0 0" xyz="0 0 0" />
            <geometry>
                <mesh filename="package://ur10_description_v3/meshes/test_finger_link.STL" />
            </geometry>
            <material name="">
                <color rgba="0 0 0 1" />
            </material>
        </visual>
        <collision>
            <origin rpy="0 0 0" xyz="0 0 0" />
            <geometry>
                <mesh filename="package://ur10_description_v3/meshes/test_finger_link.STL" />
            </geometry>
        </collision>
    </link>
    <joint name="tool0" type="fixed">
        <origin rpy="0.785398163397435 0 0" xyz="0 -0.0486072989450782 0.0984743807368732" />
        <parent link="wrist_3_link" />
        <child link="tool0_link" />
        <axis xyz="0 0 0" />
    </joint>
    <link name="camera_link">
        <inertial>
            <origin rpy="0 0 0" xyz="-1.61524861117535E-05 -0.00212700504491092 -0.0193765848255853" />
            <mass value="0.0840231018507497" />
            <inertia ixx="8.83086020963579E-06" ixy="4.69402693871799E-10" ixz="-1.85931238714756E-08" iyy="0.00010709697994186" iyz="1.0714392504519E-06" izz="0.000107821135197006" />
        </inertial>
        <visual>
                <origin xyz="0 0 0" rpy="0 0 0" />
                <geometry>
                    <mesh filename="package://ur10_description_v3/meshes/camera_link.STL" />
                </geometry>
                <material name="">
                    <color rgba="0.792156862745098 0.819607843137255 0.933333333333333 1" />
                </material>
            </visual>
        <collision>
            <origin rpy="0 0 0" xyz="0 0 0" />
            <geometry>
                <mesh filename="package://ur10_description_v3/meshes/camera_link.STL" />
            </geometry>
        </collision>
    </link>
    <joint name="tool_camera" type="fixed">
        <origin rpy="0.856180071631976 0 0" xyz="0 0.0158483827537649 0.0919267022436815" />
        <parent link="wrist_3_link" />
        <child link="camera_link" />
        <axis xyz="0 0 0" />
    </joint>
    <!-- Forces the joint to send feedback  -->
    <gazebo reference="wrist_3_joint">
        <provideFeedback>true</provideFeedback>
    </gazebo>
    <!-- The ft_sensor plugin  -->
    <gazebo>
        <plugin filename="libgazebo_ros_ft_sensor.so" name="wrist_3_joint_ft_sensor">
            <updateRate>1000.0</updateRate>
            <topicName>/wrench</topicName>
            <jointName>wrist_3_joint</jointName>
            <noise>
                <type>gaussian</type>
                <mean>0.0</mean>
                <stddev>0.003</stddev>
                <!-- change this to simulate noise -->
            </noise>
        </plugin>
    </gazebo>
    <!-- frames in the center of the camera -->
    <joint name="rgbd_camera_joint" type="fixed">
        <origin rpy="0 0 3.14" xyz="0 0 0.005" />
        <parent link="camera_link" />
        <child link="rgbd_camera_link" />
    </joint>
    <link name="rgbd_camera_link">
        <inertial>
            <origin rpy="0 0 0" xyz="-0.00936000000 -0.00003000000 -0.00273000000" />
            <mass value="0.21970000000" />
            <inertia ixx="0.00000429247" ixy="0.00000000000" ixz="0.00000002565" iyy="0.00000008027" iyz="0.00000000000" izz="0.00000427339" />
        </inertial>
        <!-- <visual>
                <geometry>
                    <box size="0.025 0.1 0.025" />
                    <<mesh filename="package://"/> 
                </geometry>
                <material name="DarkGrey"/>
            </visual> -->
        <!-- <collision>
                <geometry>
                    <box size="0.025 0.1 0.025" />
                    <mesh filename="package://"/>
                </geometry>
            </collision> -->
    </link>
    <joint name="rgbd_camera_optical_joint" type="fixed">
        <origin rpy="0 0 0" xyz="0 0 0" />
        <parent link="rgbd_camera_link" />
        <child link="rgbd_camera_optical_frame" />
    </joint>
    <link name="rgbd_camera_optical_frame">
        <inertial>
            <origin rpy="0 0 0" xyz="0 0 0" />
            <mass value="0.001" />
            <inertia ixx="0.00001" ixy="0" ixz="0" iyy="0.00001" iyz="0" izz="0.00001" />
        </inertial>
    </link>
    <!-- Depth sensor frames -->
    <joint name="rgbd_camera_depth_joint" type="fixed">
        <origin rpy="1.57 -1.57 0" xyz="-0.025 0.0 0.0" />
        <!--origin xyz="0.0 0.049 0.0" rpy="0 0 0"-->
        <parent link="rgbd_camera_link" />
        <child link="rgbd_camera_depth_frame" />
    </joint>
    <link name="rgbd_camera_depth_frame">
        <inertial>
            <origin rpy="0 0 0" xyz="0 0 0" />
            <mass value="0.001" />
            <inertia ixx="0.00001" ixy="0" ixz="0" iyy="0.00001" iyz="0" izz="0.00001" />
        </inertial>
    </link>
    <joint name="rgbd_camera_depth_optical_joint" type="fixed">
        <origin rpy="-1.5707963267948966 0.0 -1.5707963267948966" xyz="0 0 0" />
        <!-- -90 deg_to_rad - x&z -->
        <parent link="rgbd_camera_depth_frame" />
        <child link="rgbd_camera_depth_optical_frame" />
    </joint>
    <link name="rgbd_camera_depth_optical_frame">
        <inertial>
            <origin rpy="0 0 0" xyz="0 0 0" />
            <mass value="0.001" />
            <inertia ixx="0.00001" ixy="0" ixz="0" iyy="0.00001" iyz="0" izz="0.00001" />
        </inertial>
    </link>
    <!-- RGB sensor frames -->
    <joint name="rgbd_camera_rgb_joint" type="fixed">
        <origin rpy="1.57 -1.57 0" xyz="0 0 0" />
        <parent link="rgbd_camera_link" />
        <child link="rgbd_camera_rgb_frame" />
    </joint>
    <link name="rgbd_camera_rgb_frame">
        <inertial>
            <origin rpy="0 0 0" xyz="0 0 0" />
            <mass value="0.001" />
            <inertia ixx="0.00001" ixy="0" ixz="0" iyy="0.00001" iyz="0" izz="0.00001" />
        </inertial>
    </link>
    <joint name="rgbd_camera_rgb_optical_joint" type="fixed">
        <origin rpy="-1.5707963267948966 0.0 -1.5707963267948966" xyz="0 0 0" />
        <!-- -90 deg_to_rad - x&z -->
        <parent link="rgbd_camera_rgb_frame" />
        <child link="rgbd_camera_rgb_optical_frame" />
    </joint>
    <link name="rgbd_camera_rgb_optical_frame">
        <inertial>
            <origin rpy="0 0 0" xyz="0 0 0" />
            <mass value="0.001" />
            <inertia ixx="0.00001" ixy="0" ixz="0" iyy="0.00001" iyz="0" izz="0.00001" />
        </inertial>
    </link>
    <!-- ROS-Industrial 'base' frame: base_link to UR 'Base' Coordinates transform -->
    <link name="base" />
    <joint name="base_link-base_fixed_joint" type="fixed">
        <!-- Note the rotation over Z of pi radians: as base_link is REP-103
            aligned (ie: has X+ forward, Y+ left and Z+ up), this is needed
            to correctly align 'base' with the 'Base' coordinate system of
            the UR controller.
        -->
        <origin rpy="0 0 3.14" xyz="0 0 0" />
        <parent link="base_link" />
        <child link="base" />
    </joint>
    <joint name="ur10_robot_joint" type="fixed">
        <parent link="world" />
        <child link="table_link" />
        <!-- ${ur10_ns} -->
        <origin rpy="0 0 0" xyz="0 0 0" />
    </joint>
    <!-- call -->
    <!-- <xacro:moveit_quantec/> -->
    <link name="base_link_quantec">
        <inertial>
            <origin rpy="0 0 0" xyz="-0.0810107614623872 1.69806255825153E-07 0.10599645436339" />
            <mass value="97.9298238151877" />
            <inertia ixx="3.12727259199142" ixy="2.14569120944394E-06" ixz="0.467210023955441" iyy="5.52628001885015" iyz="-1.97817775090254E-06" izz="7.58545932293491" />
        </inertial>
        <visual>
            <origin rpy="0 0 0" xyz="0 0 0" />
            <geometry>
                <mesh filename="package://moveit_quantec/meshes/base_link.STL" />
            </geometry>
            <material name="">
                <color rgba="0.792156862745098 0.819607843137255 0.933333333333333 1" />
            </material>
        </visual>
        <collision>
            <origin rpy="0 0 0" xyz="0 0 0" />
            <geometry>
                <mesh filename="package://moveit_quantec/meshes/base_link.STL" />
            </geometry>
        </collision>
    </link>
    <link name="link_1">
        <inertial>
            <origin rpy="0 0 0" xyz="-0.0084665 0.019734 0.25939" />
            <mass value="94.945" />
            <inertia ixx="2.6472" ixy="-0.62895" ixz="-0.35979" iyy="6.3022" iyz="-0.17581" izz="5.5156" />
        </inertial>
        <visual>
            <origin rpy="0 0 0" xyz="0 0 0" />
            <geometry>
                <mesh filename="package://moveit_quantec/meshes/link_1.STL" />
            </geometry>
            <material name="">
                <color rgba="0.79216 0.81961 0.93333 1" />
            </material>
        </visual>
        <collision>
            <origin rpy="0 0 0" xyz="0 0 0" />
            <geometry>
                <mesh filename="package://moveit_quantec/meshes/link_1.STL" />
            </geometry>
        </collision>
    </link>
    <joint name="joint_1" type="continuous">
        <origin rpy="1.5708 0.014047 0" xyz="0 -0.235 0" />
        <parent link="base_link_quantec" />
        <child link="link_1" />
        <axis xyz="0 0 1" />
    </joint>
    <link name="link_2">
        <inertial>
            <origin rpy="0 0 0" xyz="0.0015545 -0.23159 0.40897" />
            <mass value="82.176" />
            <inertia ixx="12.398" ixy="-9.2862E-05" ixz="0.082654" iyy="12.541" iyz="0.043185" izz="0.91874" />
        </inertial>
        <visual>
            <origin rpy="0 0 0" xyz="0 0 0" />
            <geometry>
                <mesh filename="package://moveit_quantec/meshes/link_2.STL" />
            </geometry>
            <material name="">
                <color rgba="0.79216 0.81961 0.93333 1" />
            </material>
        </visual>
        <collision>
            <origin rpy="0 0 0" xyz="0 0 0" />
            <geometry>
                <mesh filename="package://moveit_quantec/meshes/link_2.STL" />
            </geometry>
        </collision>
    </link>
    <joint name="joint_2" type="continuous">
        <origin rpy="0 -0.0391 0" xyz="0.33 0 0.41772" />
        <parent link="link_1" />
        <child link="link_2" />
        <axis xyz="0 1 0" />
    </joint>
    <link name="link_3">
        <inertial>
            <origin rpy="0 0 0" xyz="0.35711 -0.015416 0.10193" />
            <mass value="47.124" />
            <inertia ixx="0.41866" ixy="-0.086691" ixz="-0.15996" iyy="3.9994" iyz="-0.042155" izz="3.9284" />
        </inertial>
        <visual>
            <origin rpy="0 0 0" xyz="0 0 0" />
            <geometry>
                <mesh filename="package://moveit_quantec/meshes/link_3.STL" />
            </geometry>
            <material name="">
                <color rgba="0.79216 0.81961 0.93333 1" />
            </material>
        </visual>
        <collision>
            <origin rpy="0 0 0" xyz="0 0 0" />
            <geometry>
                <mesh filename="package://moveit_quantec/meshes/link_3.STL" />
            </geometry>
        </collision>
    </link>
    <joint name="joint_3" type="continuous">
        <origin rpy="0 -0.52738 0" xyz="0 0 1.15" />
        <parent link="link_2" />
        <child link="link_3" />
        <axis xyz="0 1 0" />
    </joint>
    <link name="link_4">
        <inertial>
            <origin rpy="0 0 0" xyz="0.27937 0.0063685 -0.00017456" />
            <mass value="4.6744" />
            <inertia ixx="0.011503" ixy="-0.0037737" ixz="7.4652E-05" iyy="0.085293" iyz="-0.00012925" izz="0.085285" />
        </inertial>
        <visual>
            <origin rpy="0 0 0" xyz="0 0 0" />
            <geometry>
                <mesh filename="package://moveit_quantec/meshes/link_4.STL" />
            </geometry>
            <material name="">
                <color rgba="0.79216 0.81961 0.93333 1" />
            </material>
        </visual>
        <collision>
            <origin rpy="0 0 0" xyz="0 0 0" />
            <geometry>
                <mesh filename="package://moveit_quantec/meshes/link_4.STL" />
            </geometry>
        </collision>
    </link>
    <joint name="joint_4" type="continuous">
        <origin rpy="0.037095 0 0" xyz="0.78147 -0.0086752 0.115" />
        <parent link="link_3" />
        <child link="link_4" />
        <axis xyz="1 0 0" />
    </joint>
    <link name="link_5">
        <inertial>
            <origin rpy="0 0 0" xyz="0.046286 0.05529 7.0521E-05" />
            <mass value="8.3467" />
            <inertia ixx="0.035209" ixy="0.0040294" ixz="-2.9627E-05" iyy="0.059372" iyz="-0.00013764" izz="0.046632" />
        </inertial>
        <visual>
            <origin rpy="0 0 0" xyz="0 0 0" />
            <geometry>
                <mesh filename="package://moveit_quantec/meshes/link_5.STL" />
            </geometry>
            <material name="">
                <color rgba="0.79216 0.81961 0.93333 1" />
            </material>
        </visual>
        <collision>
            <origin rpy="0 0 0" xyz="0 0 0" />
            <geometry>
                <mesh filename="package://moveit_quantec/meshes/link_5.STL" />
            </geometry>
        </collision>
    </link>
    <joint name="joint_5" type="continuous">
        <origin rpy="0 0.9269 0" xyz="0.44853 0 0" />
        <parent link="link_4" />
        <child link="link_5" />
        <axis xyz="0 1 0" />
    </joint>
    <link name="link_6">
        <inertial>
            <origin rpy="0 0 0" xyz="0.021186 9.6657E-07 -3.3846E-07" />
            <mass value="0.97276" />
            <inertia ixx="0.0044336" ixy="-1.5389E-09" ixz="6.5721E-10" iyy="0.0023152" iyz="-1.9424E-09" izz="0.0023149" />
        </inertial>
        <visual>
            <origin rpy="0 0 0" xyz="0 0 0" />
            <geometry>
                <mesh filename="package://moveit_quantec/meshes/link_6.STL" />
            </geometry>
            <material name="">
                <color rgba="0.79216 0.81961 0.93333 1" />
            </material>
        </visual>
        <collision>
            <origin rpy="0 0 0" xyz="0 0 0" />
            <geometry>
                <mesh filename="package://moveit_quantec/meshes/link_6.STL" />
            </geometry>
        </collision>
    </link>
    <joint name="joint_6" type="continuous">
        <origin rpy="-2.218 0 0" xyz="0.20228 1.3733E-05 0" />
        <parent link="link_5" />
        <child link="link_6" />
        <axis xyz="1 0 0" />
    </joint>
    <joint name="quantec_robot_joint" type="fixed">
        <parent link="world" />
        <child link="base_link_quantec" />
        <!-- ${quantec_ns} -->
        <origin rpy="-1.57 0 0" xyz="-1 0.4 0" />
        <!-- Adjust xyz for the desired position -->
    </joint>
    <transmission name="trans_shoulder_pan_joint">
        <type>transmission_interface/SimpleTransmission</type>
        <joint name="shoulder_pan_joint">
            <hardwareInterface>hardware_interface/PositionJointInterface</hardwareInterface>
        </joint>
        <actuator name="shoulder_pan_joint_motor">
            <hardwareInterface>hardware_interface/PositionJointInterface</hardwareInterface>
            <mechanicalReduction>1</mechanicalReduction>
        </actuator>
    </transmission>
    <transmission name="trans_shoulder_lift_joint">
        <type>transmission_interface/SimpleTransmission</type>
        <joint name="shoulder_lift_joint">
            <hardwareInterface>hardware_interface/PositionJointInterface</hardwareInterface>
        </joint>
        <actuator name="shoulder_lift_joint_motor">
            <hardwareInterface>hardware_interface/PositionJointInterface</hardwareInterface>
            <mechanicalReduction>1</mechanicalReduction>
        </actuator>
    </transmission>
    <transmission name="trans_elbow_joint">
        <type>transmission_interface/SimpleTransmission</type>
        <joint name="elbow_joint">
            <hardwareInterface>hardware_interface/PositionJointInterface</hardwareInterface>
        </joint>
        <actuator name="elbow_joint_motor">
            <hardwareInterface>hardware_interface/PositionJointInterface</hardwareInterface>
            <mechanicalReduction>1</mechanicalReduction>
        </actuator>
    </transmission>
    <transmission name="trans_wrist_1_joint">
        <type>transmission_interface/SimpleTransmission</type>
        <joint name="wrist_1_joint">
            <hardwareInterface>hardware_interface/PositionJointInterface</hardwareInterface>
        </joint>
        <actuator name="wrist_1_joint_motor">
            <hardwareInterface>hardware_interface/PositionJointInterface</hardwareInterface>
            <mechanicalReduction>1</mechanicalReduction>
        </actuator>
    </transmission>
    <transmission name="trans_wrist_2_joint">
        <type>transmission_interface/SimpleTransmission</type>
        <joint name="wrist_2_joint">
            <hardwareInterface>hardware_interface/PositionJointInterface</hardwareInterface>
        </joint>
        <actuator name="wrist_2_joint_motor">
            <hardwareInterface>hardware_interface/PositionJointInterface</hardwareInterface>
            <mechanicalReduction>1</mechanicalReduction>
        </actuator>
    </transmission>
    <transmission name="trans_wrist_3_joint">
        <type>transmission_interface/SimpleTransmission</type>
        <joint name="wrist_3_joint">
            <hardwareInterface>hardware_interface/PositionJointInterface</hardwareInterface>
        </joint>
        <actuator name="wrist_3_joint_motor">
            <hardwareInterface>hardware_interface/PositionJointInterface</hardwareInterface>
            <mechanicalReduction>1</mechanicalReduction>
        </actuator>
    </transmission>
    <transmission name="trans_joint_1">
        <type>transmission_interface/SimpleTransmission</type>
        <joint name="joint_1">
            <hardwareInterface>hardware_interface/PositionJointInterface</hardwareInterface>
        </joint>
        <actuator name="joint_1_motor">
            <hardwareInterface>hardware_interface/PositionJointInterface</hardwareInterface>
            <mechanicalReduction>1</mechanicalReduction>
        </actuator>
    </transmission>
    <transmission name="trans_joint_2">
        <type>transmission_interface/SimpleTransmission</type>
        <joint name="joint_2">
            <hardwareInterface>hardware_interface/PositionJointInterface</hardwareInterface>
        </joint>
        <actuator name="joint_2_motor">
            <hardwareInterface>hardware_interface/PositionJointInterface</hardwareInterface>
            <mechanicalReduction>1</mechanicalReduction>
        </actuator>
    </transmission>
    <transmission name="trans_joint_3">
        <type>transmission_interface/SimpleTransmission</type>
        <joint name="joint_3">
            <hardwareInterface>hardware_interface/PositionJointInterface</hardwareInterface>
        </joint>
        <actuator name="joint_3_motor">
            <hardwareInterface>hardware_interface/PositionJointInterface</hardwareInterface>
            <mechanicalReduction>1</mechanicalReduction>
        </actuator>
    </transmission>
    <transmission name="trans_joint_4">
        <type>transmission_interface/SimpleTransmission</type>
        <joint name="joint_4">
            <hardwareInterface>hardware_interface/PositionJointInterface</hardwareInterface>
        </joint>
        <actuator name="joint_4_motor">
            <hardwareInterface>hardware_interface/PositionJointInterface</hardwareInterface>
            <mechanicalReduction>1</mechanicalReduction>
        </actuator>
    </transmission>
    <transmission name="trans_joint_5">
        <type>transmission_interface/SimpleTransmission</type>
        <joint name="joint_5">
            <hardwareInterface>hardware_interface/PositionJointInterface</hardwareInterface>
        </joint>
        <actuator name="joint_5_motor">
            <hardwareInterface>hardware_interface/PositionJointInterface</hardwareInterface>
            <mechanicalReduction>1</mechanicalReduction>
        </actuator>
    </transmission>
    <transmission name="trans_joint_6">
        <type>transmission_interface/SimpleTransmission</type>
        <joint name="joint_6">
            <hardwareInterface>hardware_interface/PositionJointInterface</hardwareInterface>
        </joint>
        <actuator name="joint_6_motor">
            <hardwareInterface>hardware_interface/PositionJointInterface</hardwareInterface>
            <mechanicalReduction>1</mechanicalReduction>
        </actuator>
    </transmission>

    <!-- controller plugins & configuration -->
    <gazebo>
        <plugin filename="libgazebo_ros_control.so" name="gazebo_ros_control">
        </plugin>
    </gazebo>

    <gazebo>
        <plugin name="joint_state_publisher" filename="libgazebo_ros_joint_state_publisher.so">
            <jointName> 
                shoulder_pan_joint,
                shoulder_lift_joint,
                elbow_joint,
                wrist_1_joint,
                wrist_2_joint,
                wrist_3_joint,
                joint_1,
                joint_2,
                joint_3,
                joint_4,
                joint_5,
                joint_6
            </jointName>
            <updateRate>10</updateRate>
        </plugin>
    </gazebo>
    
</robot>
